[32mINFO    [0m mobile_framework_logger:conftest.py:30 🚀 Starting local Appium server for this session...
[32mINFO    [0m root:appium_server.py:33 🚀 Starting Appium server...
[33mWARNING [0m urllib3.connectionpool:connectionpool.py:824 Retrying (Retry(total=2, connect=None, read=None, redirect=None, status=None)) after connection broken by 'NewConnectionError('<urllib3.connection.HTTPConnection object at 0x7f8d3782d040>: Failed to establish a new connection: [Errno 61] Connection refused')': /wd/hub/status
[33mWARNING [0m urllib3.connectionpool:connectionpool.py:824 Retrying (Retry(total=1, connect=None, read=None, redirect=None, status=None)) after connection broken by 'NewConnectionError('<urllib3.connection.HTTPConnection object at 0x7f8d37806550>: Failed to establish a new connection: [Errno 61] Connection refused')': /wd/hub/status
[33mWARNING [0m urllib3.connectionpool:connectionpool.py:824 Retrying (Retry(total=0, connect=None, read=None, redirect=None, status=None)) after connection broken by 'NewConnectionError('<urllib3.connection.HTTPConnection object at 0x7f8d37806b80>: Failed to establish a new connection: [Errno 61] Connection refused')': /wd/hub/status
[33mWARNING [0m urllib3.connectionpool:connectionpool.py:824 Retrying (Retry(total=2, connect=None, read=None, redirect=None, status=None)) after connection broken by 'NewConnectionError('<urllib3.connection.HTTPConnection object at 0x7f8d37806fa0>: Failed to establish a new connection: [Errno 61] Connection refused')': /wd/hub/status
[33mWARNING [0m urllib3.connectionpool:connectionpool.py:824 Retrying (Retry(total=1, connect=None, read=None, redirect=None, status=None)) after connection broken by 'NewConnectionError('<urllib3.connection.HTTPConnection object at 0x7f8d37806250>: Failed to establish a new connection: [Errno 61] Connection refused')': /wd/hub/status
[33mWARNING [0m urllib3.connectionpool:connectionpool.py:824 Retrying (Retry(total=0, connect=None, read=None, redirect=None, status=None)) after connection broken by 'NewConnectionError('<urllib3.connection.HTTPConnection object at 0x7f8d37806190>: Failed to establish a new connection: [Errno 61] Connection refused')': /wd/hub/status
[33mWARNING [0m urllib3.connectionpool:connectionpool.py:824 Retrying (Retry(total=2, connect=None, read=None, redirect=None, status=None)) after connection broken by 'NewConnectionError('<urllib3.connection.HTTPConnection object at 0x7f8d3782d1f0>: Failed to establish a new connection: [Errno 61] Connection refused')': /wd/hub/status
[33mWARNING [0m urllib3.connectionpool:connectionpool.py:824 Retrying (Retry(total=1, connect=None, read=None, redirect=None, status=None)) after connection broken by 'NewConnectionError('<urllib3.connection.HTTPConnection object at 0x7f8d3782d370>: Failed to establish a new connection: [Errno 61] Connection refused')': /wd/hub/status
[33mWARNING [0m urllib3.connectionpool:connectionpool.py:824 Retrying (Retry(total=0, connect=None, read=None, redirect=None, status=None)) after connection broken by 'NewConnectionError('<urllib3.connection.HTTPConnection object at 0x7f8d3782d4f0>: Failed to establish a new connection: [Errno 61] Connection refused')': /wd/hub/status
[33mWARNING [0m urllib3.connectionpool:connectionpool.py:824 Retrying (Retry(total=2, connect=None, read=None, redirect=None, status=None)) after connection broken by 'NewConnectionError('<urllib3.connection.HTTPConnection object at 0x7f8d3782d820>: Failed to establish a new connection: [Errno 61] Connection refused')': /wd/hub/status
[33mWARNING [0m urllib3.connectionpool:connectionpool.py:824 Retrying (Retry(total=1, connect=None, read=None, redirect=None, status=None)) after connection broken by 'NewConnectionError('<urllib3.connection.HTTPConnection object at 0x7f8d3782d9a0>: Failed to establish a new connection: [Errno 61] Connection refused')': /wd/hub/status
[33mWARNING [0m urllib3.connectionpool:connectionpool.py:824 Retrying (Retry(total=0, connect=None, read=None, redirect=None, status=None)) after connection broken by 'NewConnectionError('<urllib3.connection.HTTPConnection object at 0x7f8d3782db20>: Failed to establish a new connection: [Errno 61] Connection refused')': /wd/hub/status
[33mWARNING [0m urllib3.connectionpool:connectionpool.py:824 Retrying (Retry(total=2, connect=None, read=None, redirect=None, status=None)) after connection broken by 'NewConnectionError('<urllib3.connection.HTTPConnection object at 0x7f8d378068e0>: Failed to establish a new connection: [Errno 61] Connection refused')': /wd/hub/status
[33mWARNING [0m urllib3.connectionpool:connectionpool.py:824 Retrying (Retry(total=1, connect=None, read=None, redirect=None, status=None)) after connection broken by 'NewConnectionError('<urllib3.connection.HTTPConnection object at 0x7f8d3782d6a0>: Failed to establish a new connection: [Errno 61] Connection refused')': /wd/hub/status
[33mWARNING [0m urllib3.connectionpool:connectionpool.py:824 Retrying (Retry(total=0, connect=None, read=None, redirect=None, status=None)) after connection broken by 'NewConnectionError('<urllib3.connection.HTTPConnection object at 0x7f8d3782de80>: Failed to establish a new connection: [Errno 61] Connection refused')': /wd/hub/status
[33mWARNING [0m urllib3.connectionpool:connectionpool.py:824 Retrying (Retry(total=2, connect=None, read=None, redirect=None, status=None)) after connection broken by 'NewConnectionError('<urllib3.connection.HTTPConnection object at 0x7f8d378501f0>: Failed to establish a new connection: [Errno 61] Connection refused')': /wd/hub/status
[33mWARNING [0m urllib3.connectionpool:connectionpool.py:824 Retrying (Retry(total=1, connect=None, read=None, redirect=None, status=None)) after connection broken by 'NewConnectionError('<urllib3.connection.HTTPConnection object at 0x7f8d37850370>: Failed to establish a new connection: [Errno 61] Connection refused')': /wd/hub/status
[33mWARNING [0m urllib3.connectionpool:connectionpool.py:824 Retrying (Retry(total=0, connect=None, read=None, redirect=None, status=None)) after connection broken by 'NewConnectionError('<urllib3.connection.HTTPConnection object at 0x7f8d378504f0>: Failed to establish a new connection: [Errno 61] Connection refused')': /wd/hub/status
[33mWARNING [0m urllib3.connectionpool:connectionpool.py:824 Retrying (Retry(total=2, connect=None, read=None, redirect=None, status=None)) after connection broken by 'NewConnectionError('<urllib3.connection.HTTPConnection object at 0x7f8d37850820>: Failed to establish a new connection: [Errno 61] Connection refused')': /wd/hub/status
[33mWARNING [0m urllib3.connectionpool:connectionpool.py:824 Retrying (Retry(total=1, connect=None, read=None, redirect=None, status=None)) after connection broken by 'NewConnectionError('<urllib3.connection.HTTPConnection object at 0x7f8d378509a0>: Failed to establish a new connection: [Errno 61] Connection refused')': /wd/hub/status
[33mWARNING [0m urllib3.connectionpool:connectionpool.py:824 Retrying (Retry(total=0, connect=None, read=None, redirect=None, status=None)) after connection broken by 'NewConnectionError('<urllib3.connection.HTTPConnection object at 0x7f8d37850b20>: Failed to establish a new connection: [Errno 61] Connection refused')': /wd/hub/status
[33mWARNING [0m urllib3.connectionpool:connectionpool.py:824 Retrying (Retry(total=2, connect=None, read=None, redirect=None, status=None)) after connection broken by 'NewConnectionError('<urllib3.connection.HTTPConnection object at 0x7f8d37850e50>: Failed to establish a new connection: [Errno 61] Connection refused')': /wd/hub/status
[33mWARNING [0m urllib3.connectionpool:connectionpool.py:824 Retrying (Retry(total=1, connect=None, read=None, redirect=None, status=None)) after connection broken by 'NewConnectionError('<urllib3.connection.HTTPConnection object at 0x7f8d37850fd0>: Failed to establish a new connection: [Errno 61] Connection refused')': /wd/hub/status
[33mWARNING [0m urllib3.connectionpool:connectionpool.py:824 Retrying (Retry(total=0, connect=None, read=None, redirect=None, status=None)) after connection broken by 'NewConnectionError('<urllib3.connection.HTTPConnection object at 0x7f8d3786d190>: Failed to establish a new connection: [Errno 61] Connection refused')': /wd/hub/status
[33mWARNING [0m urllib3.connectionpool:connectionpool.py:824 Retrying (Retry(total=2, connect=None, read=None, redirect=None, status=None)) after connection broken by 'NewConnectionError('<urllib3.connection.HTTPConnection object at 0x7f8d37850070>: Failed to establish a new connection: [Errno 61] Connection refused')': /wd/hub/status
[33mWARNING [0m urllib3.connectionpool:connectionpool.py:824 Retrying (Retry(total=1, connect=None, read=None, redirect=None, status=None)) after connection broken by 'NewConnectionError('<urllib3.connection.HTTPConnection object at 0x7f8d3786d2b0>: Failed to establish a new connection: [Errno 61] Connection refused')': /wd/hub/status
[33mWARNING [0m urllib3.connectionpool:connectionpool.py:824 Retrying (Retry(total=0, connect=None, read=None, redirect=None, status=None)) after connection broken by 'NewConnectionError('<urllib3.connection.HTTPConnection object at 0x7f8d3786d400>: Failed to establish a new connection: [Errno 61] Connection refused')': /wd/hub/status
[33mWARNING [0m urllib3.connectionpool:connectionpool.py:824 Retrying (Retry(total=2, connect=None, read=None, redirect=None, status=None)) after connection broken by 'NewConnectionError('<urllib3.connection.HTTPConnection object at 0x7f8d3786d730>: Failed to establish a new connection: [Errno 61] Connection refused')': /wd/hub/status
[33mWARNING [0m urllib3.connectionpool:connectionpool.py:824 Retrying (Retry(total=1, connect=None, read=None, redirect=None, status=None)) after connection broken by 'NewConnectionError('<urllib3.connection.HTTPConnection object at 0x7f8d3786d8b0>: Failed to establish a new connection: [Errno 61] Connection refused')': /wd/hub/status
[33mWARNING [0m urllib3.connectionpool:connectionpool.py:824 Retrying (Retry(total=0, connect=None, read=None, redirect=None, status=None)) after connection broken by 'NewConnectionError('<urllib3.connection.HTTPConnection object at 0x7f8d3786da30>: Failed to establish a new connection: [Errno 61] Connection refused')': /wd/hub/status
[33mWARNING [0m urllib3.connectionpool:connectionpool.py:824 Retrying (Retry(total=2, connect=None, read=None, redirect=None, status=None)) after connection broken by 'NewConnectionError('<urllib3.connection.HTTPConnection object at 0x7f8d3786dd60>: Failed to establish a new connection: [Errno 61] Connection refused')': /wd/hub/status
[33mWARNING [0m urllib3.connectionpool:connectionpool.py:824 Retrying (Retry(total=1, connect=None, read=None, redirect=None, status=None)) after connection broken by 'NewConnectionError('<urllib3.connection.HTTPConnection object at 0x7f8d3786dee0>: Failed to establish a new connection: [Errno 61] Connection refused')': /wd/hub/status
[33mWARNING [0m urllib3.connectionpool:connectionpool.py:824 Retrying (Retry(total=0, connect=None, read=None, redirect=None, status=None)) after connection broken by 'NewConnectionError('<urllib3.connection.HTTPConnection object at 0x7f8d378830a0>: Failed to establish a new connection: [Errno 61] Connection refused')': /wd/hub/status
[33mWARNING [0m urllib3.connectionpool:connectionpool.py:824 Retrying (Retry(total=2, connect=None, read=None, redirect=None, status=None)) after connection broken by 'NewConnectionError('<urllib3.connection.HTTPConnection object at 0x7f8d378833d0>: Failed to establish a new connection: [Errno 61] Connection refused')': /wd/hub/status
[33mWARNING [0m urllib3.connectionpool:connectionpool.py:824 Retrying (Retry(total=1, connect=None, read=None, redirect=None, status=None)) after connection broken by 'NewConnectionError('<urllib3.connection.HTTPConnection object at 0x7f8d37883550>: Failed to establish a new connection: [Errno 61] Connection refused')': /wd/hub/status
[33mWARNING [0m urllib3.connectionpool:connectionpool.py:824 Retrying (Retry(total=0, connect=None, read=None, redirect=None, status=None)) after connection broken by 'NewConnectionError('<urllib3.connection.HTTPConnection object at 0x7f8d3786dbe0>: Failed to establish a new connection: [Errno 61] Connection refused')': /wd/hub/status
[33mWARNING [0m urllib3.connectionpool:connectionpool.py:824 Retrying (Retry(total=2, connect=None, read=None, redirect=None, status=None)) after connection broken by 'NewConnectionError('<urllib3.connection.HTTPConnection object at 0x7f8d378832b0>: Failed to establish a new connection: [Errno 61] Connection refused')': /wd/hub/status
[33mWARNING [0m urllib3.connectionpool:connectionpool.py:824 Retrying (Retry(total=1, connect=None, read=None, redirect=None, status=None)) after connection broken by 'NewConnectionError('<urllib3.connection.HTTPConnection object at 0x7f8d378837c0>: Failed to establish a new connection: [Errno 61] Connection refused')': /wd/hub/status
[33mWARNING [0m urllib3.connectionpool:connectionpool.py:824 Retrying (Retry(total=0, connect=None, read=None, redirect=None, status=None)) after connection broken by 'NewConnectionError('<urllib3.connection.HTTPConnection object at 0x7f8d37883940>: Failed to establish a new connection: [Errno 61] Connection refused')': /wd/hub/status
[33mWARNING [0m urllib3.connectionpool:connectionpool.py:824 Retrying (Retry(total=2, connect=None, read=None, redirect=None, status=None)) after connection broken by 'NewConnectionError('<urllib3.connection.HTTPConnection object at 0x7f8d37883c70>: Failed to establish a new connection: [Errno 61] Connection refused')': /wd/hub/status
[33mWARNING [0m urllib3.connectionpool:connectionpool.py:824 Retrying (Retry(total=1, connect=None, read=None, redirect=None, status=None)) after connection broken by 'NewConnectionError('<urllib3.connection.HTTPConnection object at 0x7f8d37883df0>: Failed to establish a new connection: [Errno 61] Connection refused')': /wd/hub/status
[33mWARNING [0m urllib3.connectionpool:connectionpool.py:824 Retrying (Retry(total=0, connect=None, read=None, redirect=None, status=None)) after connection broken by 'NewConnectionError('<urllib3.connection.HTTPConnection object at 0x7f8d37883f70>: Failed to establish a new connection: [Errno 61] Connection refused')': /wd/hub/status
[33mWARNING [0m urllib3.connectionpool:connectionpool.py:824 Retrying (Retry(total=2, connect=None, read=None, redirect=None, status=None)) after connection broken by 'NewConnectionError('<urllib3.connection.HTTPConnection object at 0x7f8d3789f2e0>: Failed to establish a new connection: [Errno 61] Connection refused')': /wd/hub/status
[33mWARNING [0m urllib3.connectionpool:connectionpool.py:824 Retrying (Retry(total=1, connect=None, read=None, redirect=None, status=None)) after connection broken by 'NewConnectionError('<urllib3.connection.HTTPConnection object at 0x7f8d3789f460>: Failed to establish a new connection: [Errno 61] Connection refused')': /wd/hub/status
[33mWARNING [0m urllib3.connectionpool:connectionpool.py:824 Retrying (Retry(total=0, connect=None, read=None, redirect=None, status=None)) after connection broken by 'NewConnectionError('<urllib3.connection.HTTPConnection object at 0x7f8d3789f5e0>: Failed to establish a new connection: [Errno 61] Connection refused')': /wd/hub/status
[33mWARNING [0m urllib3.connectionpool:connectionpool.py:824 Retrying (Retry(total=2, connect=None, read=None, redirect=None, status=None)) after connection broken by 'NewConnectionError('<urllib3.connection.HTTPConnection object at 0x7f8d3789f910>: Failed to establish a new connection: [Errno 61] Connection refused')': /wd/hub/status
[33mWARNING [0m urllib3.connectionpool:connectionpool.py:824 Retrying (Retry(total=1, connect=None, read=None, redirect=None, status=None)) after connection broken by 'NewConnectionError('<urllib3.connection.HTTPConnection object at 0x7f8d3789fa90>: Failed to establish a new connection: [Errno 61] Connection refused')': /wd/hub/status
[33mWARNING [0m urllib3.connectionpool:connectionpool.py:824 Retrying (Retry(total=0, connect=None, read=None, redirect=None, status=None)) after connection broken by 'NewConnectionError('<urllib3.connection.HTTPConnection object at 0x7f8d37850d60>: Failed to establish a new connection: [Errno 61] Connection refused')': /wd/hub/status
[33mWARNING [0m urllib3.connectionpool:connectionpool.py:824 Retrying (Retry(total=2, connect=None, read=None, redirect=None, status=None)) after connection broken by 'NewConnectionError('<urllib3.connection.HTTPConnection object at 0x7f8d3789fb80>: Failed to establish a new connection: [Errno 61] Connection refused')': /wd/hub/status
[33mWARNING [0m urllib3.connectionpool:connectionpool.py:824 Retrying (Retry(total=1, connect=None, read=None, redirect=None, status=None)) after connection broken by 'NewConnectionError('<urllib3.connection.HTTPConnection object at 0x7f8d3789fd00>: Failed to establish a new connection: [Errno 61] Connection refused')': /wd/hub/status
[33mWARNING [0m urllib3.connectionpool:connectionpool.py:824 Retrying (Retry(total=0, connect=None, read=None, redirect=None, status=None)) after connection broken by 'NewConnectionError('<urllib3.connection.HTTPConnection object at 0x7f8d3789fe80>: Failed to establish a new connection: [Errno 61] Connection refused')': /wd/hub/status
[33mWARNING [0m urllib3.connectionpool:connectionpool.py:824 Retrying (Retry(total=2, connect=None, read=None, redirect=None, status=None)) after connection broken by 'NewConnectionError('<urllib3.connection.HTTPConnection object at 0x7f8d378b61f0>: Failed to establish a new connection: [Errno 61] Connection refused')': /wd/hub/status
[33mWARNING [0m urllib3.connectionpool:connectionpool.py:824 Retrying (Retry(total=1, connect=None, read=None, redirect=None, status=None)) after connection broken by 'NewConnectionError('<urllib3.connection.HTTPConnection object at 0x7f8d378b6370>: Failed to establish a new connection: [Errno 61] Connection refused')': /wd/hub/status
[33mWARNING [0m urllib3.connectionpool:connectionpool.py:824 Retrying (Retry(total=0, connect=None, read=None, redirect=None, status=None)) after connection broken by 'NewConnectionError('<urllib3.connection.HTTPConnection object at 0x7f8d378b64f0>: Failed to establish a new connection: [Errno 61] Connection refused')': /wd/hub/status
[32mINFO    [0m root:appium_server.py:21 ✅ Appium is running at http://127.0.0.1:4723/wd/hub/status
[32mINFO    [0m root:appium_server.py:40 ✅ Appium server started successfully after 1 seconds.
[32mINFO    [0m mobile_framework_logger:conftest.py:23 🔍 Selected platform: android
[32mINFO    [0m mobile_framework_logger:conftest.py:41 🚗 Initializing driver for platform: android
[32mINFO    [0m root:driver_manager.py:17 🔍 Checking CONFIG for platform: android
[32mINFO    [0m root:driver_manager.py:34 🚀 Starting Appium driver for android (None) with capabilities: {'platformName': 'Android', 'appium:app': '/Users/susannakarapetyan/gap_mobile/mobile_automation_framework/apps/android_qa.apk', 'appium:deviceName': 'emulator-5554', 'appium:udid': 'RZ8R71C78VW', 'appium:platformVersion': '10.0', 'appium:automationName': 'UiAutomator2', 'project': 'Genius Meter App', 'build': 'Regression Build 1', 'name': 'Android Test', 'server_url': 'http://127.0.0.1:4723/wd/hub'}
[32mINFO    [0m root:driver_manager.py:47 ✅ ANDROID driver for None started.
[32mINFO    [0m mobile_framework_logger:create_genius_team_successfully_tests.py:20 🔹 Setting up Login Test
[32mINFO    [0m mobile_framework_logger:create_genius_team_successfully_tests.py:26 🔄 Restarting App for a fresh session...
[32mINFO    [0m mobile_framework_logger:create_genius_team_successfully_tests.py:31 🔍 Running on platform: Android
[32mINFO    [0m mobile_framework_logger:login_page.py:12 🔍 Initializing LoginPage with platform: Android
[32mINFO    [0m mobile_framework_logger:login_page.py:23 🔄 Verifying that the login screen is displayed on Android...
[32mINFO    [0m mobile_framework_logger:login_page.py:31 ✅ Login screen is displayed on Android.
[32mINFO    [0m mobile_framework_logger:create_genius_team_successfully_tests.py:40 🔹 Running valid login test on: Android
[32mINFO    [0m mobile_framework_logger:create_genius_team_successfully_tests.py:44 🔐 Logging in with: NewLGOBCO1@mailinator.com / qwe123QWE!@#
[32mINFO    [0m mobile_framework_logger:login_page.py:39 🔹 Performing valid login on Android with email: NewLGOBCO1@mailinator.com
[32mINFO    [0m mobile_framework_logger:base_page.py:36 ✅ Sent keys to ('id', 'com.gapinternational.genius.qa:id/emailEditText'): NewLGOBCO1@mailinator.com
[32mINFO    [0m mobile_framework_logger:base_page.py:36 ✅ Sent keys to ('id', 'com.gapinternational.genius.qa:id/passwordEditText'): qwe123QWE!@#
[32mINFO    [0m mobile_framework_logger:base_page.py:25 ✅ Clicked on ('id', 'com.gapinternational.genius.qa:id/signInButton')
[32mINFO    [0m mobile_framework_logger:login_page.py:54 ✅ Login button clicked successfully.
[32mINFO    [0m mobile_framework_logger:dashboard_page.py:34 ✅ Dashboard tab is visible on the Dashboard.
[32mINFO    [0m mobile_framework_logger:create_genius_team_successfully_tests.py:47 ✅ Login test completed successfully!
[32mINFO    [0m mobile_framework_logger:dashboard_page.py:54 🔹 Clicking GM tab...
[32mINFO    [0m mobile_framework_logger:base_page.py:25 ✅ Clicked on ('id', 'com.gapinternational.genius.qa:id/group')
[32mINFO    [0m mobile_framework_logger:dashboard_page.py:56 ✅ GM tab clicked successfully!
[32mINFO    [0m mobile_framework_logger:GM_page.py:21 🔹 Scrolling to the bottom of the GM page...
[32mINFO    [0m mobile_framework_logger:base_page.py:179 ✅ Element 'create_team_btn' is already visible. No scrolling needed.
[32mINFO    [0m mobile_framework_logger:GM_page.py:26 ✅ Reached the bottom of the GM page.
[32mINFO    [0m mobile_framework_logger:GM_page.py:37 🔹 Clicking Create a team...
[31m[1mERROR   [0m mobile_framework_logger:base_page.py:27 ❌ Failed to click element ('id', 'com.gapinternational.genius.qa:id/createGroupButton'): Message: 
Stacktrace:
NoSuchElementError: An element could not be located on the page using the given search parameters.
    at AndroidUiautomator2Driver.findElOrEls (/Users/susannakarapetyan/.appium/node_modules/appium-uiautomator2-driver/node_modules/appium-android-driver/lib/commands/find.ts:86:11)
    at processTicksAndRejections (node:internal/process/task_queues:105:5)
    at AndroidUiautomator2Driver.findElOrElsWithProcessing (/usr/local/lib/node_modules/appium/node_modules/@appium/base-driver/lib/basedriver/commands/find.ts:60:12)
    at AndroidUiautomator2Driver.findElement (/usr/local/lib/node_modules/appium/node_modules/@appium/base-driver/lib/basedriver/commands/find.ts:75:12)
[31m[1mERROR   [0m mobile_framework_logger:GM_page.py:42 ❌ Create a team could not be clicked: Message: 
Stacktrace:
NoSuchElementError: An element could not be located on the page using the given search parameters.
    at AndroidUiautomator2Driver.findElOrEls (/Users/susannakarapetyan/.appium/node_modules/appium-uiautomator2-driver/node_modules/appium-android-driver/lib/commands/find.ts:86:11)
    at processTicksAndRejections (node:internal/process/task_queues:105:5)
    at AndroidUiautomator2Driver.findElOrElsWithProcessing (/usr/local/lib/node_modules/appium/node_modules/@appium/base-driver/lib/basedriver/commands/find.ts:60:12)
    at AndroidUiautomator2Driver.findElement (/usr/local/lib/node_modules/appium/node_modules/@appium/base-driver/lib/basedriver/commands/find.ts:75:12)
[32mINFO    [0m mobile_framework_logger:GM_page.py:47 📸 Screenshot saved: logs/Create a team_not_clicked.png
[32mINFO    [0m mobile_framework_logger:conftest.py:53 🛑 Quitting driver after test...
[32mINFO    [0m mobile_framework_logger:conftest.py:33 🛑 Stopping Appium server...
[32mINFO    [0m root:appium_server.py:50 🛑 Stopping Appium server...
[32mINFO    [0m root:appium_server.py:52 ✅ Appium server stopped.