[32mINFO    [0m mobile_framework_logger:conftest.py:30 🚀 Starting local Appium server for this session...
[32mINFO    [0m root:appium_server.py:33 🚀 Starting Appium server...
[33mWARNING [0m urllib3.connectionpool:connectionpool.py:824 Retrying (Retry(total=2, connect=None, read=None, redirect=None, status=None)) after connection broken by 'NewConnectionError('<urllib3.connection.HTTPConnection object at 0x7fed21110d90>: Failed to establish a new connection: [Errno 61] Connection refused')': /wd/hub/status
[33mWARNING [0m urllib3.connectionpool:connectionpool.py:824 Retrying (Retry(total=1, connect=None, read=None, redirect=None, status=None)) after connection broken by 'NewConnectionError('<urllib3.connection.HTTPConnection object at 0x7fed21110f10>: Failed to establish a new connection: [Errno 61] Connection refused')': /wd/hub/status
[33mWARNING [0m urllib3.connectionpool:connectionpool.py:824 Retrying (Retry(total=0, connect=None, read=None, redirect=None, status=None)) after connection broken by 'NewConnectionError('<urllib3.connection.HTTPConnection object at 0x7fed211330d0>: Failed to establish a new connection: [Errno 61] Connection refused')': /wd/hub/status
[33mWARNING [0m urllib3.connectionpool:connectionpool.py:824 Retrying (Retry(total=2, connect=None, read=None, redirect=None, status=None)) after connection broken by 'NewConnectionError('<urllib3.connection.HTTPConnection object at 0x7fed211333a0>: Failed to establish a new connection: [Errno 61] Connection refused')': /wd/hub/status
[33mWARNING [0m urllib3.connectionpool:connectionpool.py:824 Retrying (Retry(total=1, connect=None, read=None, redirect=None, status=None)) after connection broken by 'NewConnectionError('<urllib3.connection.HTTPConnection object at 0x7fed211334c0>: Failed to establish a new connection: [Errno 61] Connection refused')': /wd/hub/status
[33mWARNING [0m urllib3.connectionpool:connectionpool.py:824 Retrying (Retry(total=0, connect=None, read=None, redirect=None, status=None)) after connection broken by 'NewConnectionError('<urllib3.connection.HTTPConnection object at 0x7fed21133640>: Failed to establish a new connection: [Errno 61] Connection refused')': /wd/hub/status
[33mWARNING [0m urllib3.connectionpool:connectionpool.py:824 Retrying (Retry(total=2, connect=None, read=None, redirect=None, status=None)) after connection broken by 'NewConnectionError('<urllib3.connection.HTTPConnection object at 0x7fed210ece80>: Failed to establish a new connection: [Errno 61] Connection refused')': /wd/hub/status
[33mWARNING [0m urllib3.connectionpool:connectionpool.py:824 Retrying (Retry(total=1, connect=None, read=None, redirect=None, status=None)) after connection broken by 'NewConnectionError('<urllib3.connection.HTTPConnection object at 0x7fed210ecdc0>: Failed to establish a new connection: [Errno 61] Connection refused')': /wd/hub/status
[33mWARNING [0m urllib3.connectionpool:connectionpool.py:824 Retrying (Retry(total=0, connect=None, read=None, redirect=None, status=None)) after connection broken by 'NewConnectionError('<urllib3.connection.HTTPConnection object at 0x7fed211100a0>: Failed to establish a new connection: [Errno 61] Connection refused')': /wd/hub/status
[33mWARNING [0m urllib3.connectionpool:connectionpool.py:824 Retrying (Retry(total=2, connect=None, read=None, redirect=None, status=None)) after connection broken by 'NewConnectionError('<urllib3.connection.HTTPConnection object at 0x7fed21110880>: Failed to establish a new connection: [Errno 61] Connection refused')': /wd/hub/status
[33mWARNING [0m urllib3.connectionpool:connectionpool.py:824 Retrying (Retry(total=1, connect=None, read=None, redirect=None, status=None)) after connection broken by 'NewConnectionError('<urllib3.connection.HTTPConnection object at 0x7fed21110820>: Failed to establish a new connection: [Errno 61] Connection refused')': /wd/hub/status
[33mWARNING [0m urllib3.connectionpool:connectionpool.py:824 Retrying (Retry(total=0, connect=None, read=None, redirect=None, status=None)) after connection broken by 'NewConnectionError('<urllib3.connection.HTTPConnection object at 0x7fed21133940>: Failed to establish a new connection: [Errno 61] Connection refused')': /wd/hub/status
[33mWARNING [0m urllib3.connectionpool:connectionpool.py:824 Retrying (Retry(total=2, connect=None, read=None, redirect=None, status=None)) after connection broken by 'NewConnectionError('<urllib3.connection.HTTPConnection object at 0x7fed21133b20>: Failed to establish a new connection: [Errno 61] Connection refused')': /wd/hub/status
[33mWARNING [0m urllib3.connectionpool:connectionpool.py:824 Retrying (Retry(total=1, connect=None, read=None, redirect=None, status=None)) after connection broken by 'NewConnectionError('<urllib3.connection.HTTPConnection object at 0x7fed21133ca0>: Failed to establish a new connection: [Errno 61] Connection refused')': /wd/hub/status
[33mWARNING [0m urllib3.connectionpool:connectionpool.py:824 Retrying (Retry(total=0, connect=None, read=None, redirect=None, status=None)) after connection broken by 'NewConnectionError('<urllib3.connection.HTTPConnection object at 0x7fed21133e20>: Failed to establish a new connection: [Errno 61] Connection refused')': /wd/hub/status
[33mWARNING [0m urllib3.connectionpool:connectionpool.py:824 Retrying (Retry(total=2, connect=None, read=None, redirect=None, status=None)) after connection broken by 'NewConnectionError('<urllib3.connection.HTTPConnection object at 0x7fed2115a190>: Failed to establish a new connection: [Errno 61] Connection refused')': /wd/hub/status
[33mWARNING [0m urllib3.connectionpool:connectionpool.py:824 Retrying (Retry(total=1, connect=None, read=None, redirect=None, status=None)) after connection broken by 'NewConnectionError('<urllib3.connection.HTTPConnection object at 0x7fed2115a310>: Failed to establish a new connection: [Errno 61] Connection refused')': /wd/hub/status
[33mWARNING [0m urllib3.connectionpool:connectionpool.py:824 Retrying (Retry(total=0, connect=None, read=None, redirect=None, status=None)) after connection broken by 'NewConnectionError('<urllib3.connection.HTTPConnection object at 0x7fed2115a490>: Failed to establish a new connection: [Errno 61] Connection refused')': /wd/hub/status
[33mWARNING [0m urllib3.connectionpool:connectionpool.py:824 Retrying (Retry(total=2, connect=None, read=None, redirect=None, status=None)) after connection broken by 'NewConnectionError('<urllib3.connection.HTTPConnection object at 0x7fed211339a0>: Failed to establish a new connection: [Errno 61] Connection refused')': /wd/hub/status
[33mWARNING [0m urllib3.connectionpool:connectionpool.py:824 Retrying (Retry(total=1, connect=None, read=None, redirect=None, status=None)) after connection broken by 'NewConnectionError('<urllib3.connection.HTTPConnection object at 0x7fed2115a040>: Failed to establish a new connection: [Errno 61] Connection refused')': /wd/hub/status
[33mWARNING [0m urllib3.connectionpool:connectionpool.py:824 Retrying (Retry(total=0, connect=None, read=None, redirect=None, status=None)) after connection broken by 'NewConnectionError('<urllib3.connection.HTTPConnection object at 0x7fed2115a7f0>: Failed to establish a new connection: [Errno 61] Connection refused')': /wd/hub/status
[33mWARNING [0m urllib3.connectionpool:connectionpool.py:824 Retrying (Retry(total=2, connect=None, read=None, redirect=None, status=None)) after connection broken by 'NewConnectionError('<urllib3.connection.HTTPConnection object at 0x7fed2115ab20>: Failed to establish a new connection: [Errno 61] Connection refused')': /wd/hub/status
[33mWARNING [0m urllib3.connectionpool:connectionpool.py:824 Retrying (Retry(total=1, connect=None, read=None, redirect=None, status=None)) after connection broken by 'NewConnectionError('<urllib3.connection.HTTPConnection object at 0x7fed2115aca0>: Failed to establish a new connection: [Errno 61] Connection refused')': /wd/hub/status
[33mWARNING [0m urllib3.connectionpool:connectionpool.py:824 Retrying (Retry(total=0, connect=None, read=None, redirect=None, status=None)) after connection broken by 'NewConnectionError('<urllib3.connection.HTTPConnection object at 0x7fed2115ae20>: Failed to establish a new connection: [Errno 61] Connection refused')': /wd/hub/status
[33mWARNING [0m urllib3.connectionpool:connectionpool.py:824 Retrying (Retry(total=2, connect=None, read=None, redirect=None, status=None)) after connection broken by 'NewConnectionError('<urllib3.connection.HTTPConnection object at 0x7fed21159190>: Failed to establish a new connection: [Errno 61] Connection refused')': /wd/hub/status
[33mWARNING [0m urllib3.connectionpool:connectionpool.py:824 Retrying (Retry(total=1, connect=None, read=None, redirect=None, status=None)) after connection broken by 'NewConnectionError('<urllib3.connection.HTTPConnection object at 0x7fed21159310>: Failed to establish a new connection: [Errno 61] Connection refused')': /wd/hub/status
[33mWARNING [0m urllib3.connectionpool:connectionpool.py:824 Retrying (Retry(total=0, connect=None, read=None, redirect=None, status=None)) after connection broken by 'NewConnectionError('<urllib3.connection.HTTPConnection object at 0x7fed21159490>: Failed to establish a new connection: [Errno 61] Connection refused')': /wd/hub/status
[33mWARNING [0m urllib3.connectionpool:connectionpool.py:824 Retrying (Retry(total=2, connect=None, read=None, redirect=None, status=None)) after connection broken by 'NewConnectionError('<urllib3.connection.HTTPConnection object at 0x7fed211597c0>: Failed to establish a new connection: [Errno 61] Connection refused')': /wd/hub/status
[33mWARNING [0m urllib3.connectionpool:connectionpool.py:824 Retrying (Retry(total=1, connect=None, read=None, redirect=None, status=None)) after connection broken by 'NewConnectionError('<urllib3.connection.HTTPConnection object at 0x7fed21159940>: Failed to establish a new connection: [Errno 61] Connection refused')': /wd/hub/status
[33mWARNING [0m urllib3.connectionpool:connectionpool.py:824 Retrying (Retry(total=0, connect=None, read=None, redirect=None, status=None)) after connection broken by 'NewConnectionError('<urllib3.connection.HTTPConnection object at 0x7fed21159ac0>: Failed to establish a new connection: [Errno 61] Connection refused')': /wd/hub/status
[33mWARNING [0m urllib3.connectionpool:connectionpool.py:824 Retrying (Retry(total=2, connect=None, read=None, redirect=None, status=None)) after connection broken by 'NewConnectionError('<urllib3.connection.HTTPConnection object at 0x7fed21159610>: Failed to establish a new connection: [Errno 61] Connection refused')': /wd/hub/status
[33mWARNING [0m urllib3.connectionpool:connectionpool.py:824 Retrying (Retry(total=1, connect=None, read=None, redirect=None, status=None)) after connection broken by 'NewConnectionError('<urllib3.connection.HTTPConnection object at 0x7fed21159bb0>: Failed to establish a new connection: [Errno 61] Connection refused')': /wd/hub/status
[33mWARNING [0m urllib3.connectionpool:connectionpool.py:824 Retrying (Retry(total=0, connect=None, read=None, redirect=None, status=None)) after connection broken by 'NewConnectionError('<urllib3.connection.HTTPConnection object at 0x7fed21159d30>: Failed to establish a new connection: [Errno 61] Connection refused')': /wd/hub/status
[33mWARNING [0m urllib3.connectionpool:connectionpool.py:824 Retrying (Retry(total=2, connect=None, read=None, redirect=None, status=None)) after connection broken by 'NewConnectionError('<urllib3.connection.HTTPConnection object at 0x7fed2118e0a0>: Failed to establish a new connection: [Errno 61] Connection refused')': /wd/hub/status
[33mWARNING [0m urllib3.connectionpool:connectionpool.py:824 Retrying (Retry(total=1, connect=None, read=None, redirect=None, status=None)) after connection broken by 'NewConnectionError('<urllib3.connection.HTTPConnection object at 0x7fed2118e220>: Failed to establish a new connection: [Errno 61] Connection refused')': /wd/hub/status
[33mWARNING [0m urllib3.connectionpool:connectionpool.py:824 Retrying (Retry(total=0, connect=None, read=None, redirect=None, status=None)) after connection broken by 'NewConnectionError('<urllib3.connection.HTTPConnection object at 0x7fed2118e3a0>: Failed to establish a new connection: [Errno 61] Connection refused')': /wd/hub/status
[33mWARNING [0m urllib3.connectionpool:connectionpool.py:824 Retrying (Retry(total=2, connect=None, read=None, redirect=None, status=None)) after connection broken by 'NewConnectionError('<urllib3.connection.HTTPConnection object at 0x7fed2118e6d0>: Failed to establish a new connection: [Errno 61] Connection refused')': /wd/hub/status
[33mWARNING [0m urllib3.connectionpool:connectionpool.py:824 Retrying (Retry(total=1, connect=None, read=None, redirect=None, status=None)) after connection broken by 'NewConnectionError('<urllib3.connection.HTTPConnection object at 0x7fed2118e850>: Failed to establish a new connection: [Errno 61] Connection refused')': /wd/hub/status
[33mWARNING [0m urllib3.connectionpool:connectionpool.py:824 Retrying (Retry(total=0, connect=None, read=None, redirect=None, status=None)) after connection broken by 'NewConnectionError('<urllib3.connection.HTTPConnection object at 0x7fed2118e9d0>: Failed to establish a new connection: [Errno 61] Connection refused')': /wd/hub/status
[33mWARNING [0m urllib3.connectionpool:connectionpool.py:824 Retrying (Retry(total=2, connect=None, read=None, redirect=None, status=None)) after connection broken by 'NewConnectionError('<urllib3.connection.HTTPConnection object at 0x7fed2118ed00>: Failed to establish a new connection: [Errno 61] Connection refused')': /wd/hub/status
[33mWARNING [0m urllib3.connectionpool:connectionpool.py:824 Retrying (Retry(total=1, connect=None, read=None, redirect=None, status=None)) after connection broken by 'NewConnectionError('<urllib3.connection.HTTPConnection object at 0x7fed2118ee80>: Failed to establish a new connection: [Errno 61] Connection refused')': /wd/hub/status
[33mWARNING [0m urllib3.connectionpool:connectionpool.py:824 Retrying (Retry(total=0, connect=None, read=None, redirect=None, status=None)) after connection broken by 'NewConnectionError('<urllib3.connection.HTTPConnection object at 0x7fed21159f70>: Failed to establish a new connection: [Errno 61] Connection refused')': /wd/hub/status
[33mWARNING [0m urllib3.connectionpool:connectionpool.py:824 Retrying (Retry(total=2, connect=None, read=None, redirect=None, status=None)) after connection broken by 'NewConnectionError('<urllib3.connection.HTTPConnection object at 0x7fed2118efa0>: Failed to establish a new connection: [Errno 61] Connection refused')': /wd/hub/status
[33mWARNING [0m urllib3.connectionpool:connectionpool.py:824 Retrying (Retry(total=1, connect=None, read=None, redirect=None, status=None)) after connection broken by 'NewConnectionError('<urllib3.connection.HTTPConnection object at 0x7fed211ab130>: Failed to establish a new connection: [Errno 61] Connection refused')': /wd/hub/status
[33mWARNING [0m urllib3.connectionpool:connectionpool.py:824 Retrying (Retry(total=0, connect=None, read=None, redirect=None, status=None)) after connection broken by 'NewConnectionError('<urllib3.connection.HTTPConnection object at 0x7fed211ab2b0>: Failed to establish a new connection: [Errno 61] Connection refused')': /wd/hub/status
[32mINFO    [0m root:appium_server.py:21 ✅ Appium is running at http://127.0.0.1:4723/wd/hub/status
[32mINFO    [0m root:appium_server.py:40 ✅ Appium server started successfully after 1 seconds.
[32mINFO    [0m mobile_framework_logger:conftest.py:23 🔍 Selected platform: android
[32mINFO    [0m mobile_framework_logger:conftest.py:41 🚗 Initializing driver for platform: android
[32mINFO    [0m root:driver_manager.py:64 🔍 Requested platform: android
[32mINFO    [0m root:driver_manager.py:75 📡 Using Appium server: http://127.0.0.1:4723/wd/hub
[32mINFO    [0m root:driver_manager.py:78 📦 Capabilities for android: {'platformName': 'Android', 'appium:app': 'bs://27830fbf3f3c09b920c436c31ac90009279dab6d', 'appium:deviceName': 'GooglePixel6', 'appium:platformVersion': '12.0', 'appium:automationName': 'UiAutomator2', 'project': 'Genius Meter App', 'build': 'Regression Build 1', 'name': 'Android Test', 'server_url': 'http://127.0.0.1:4723/wd/hub'}
[31m[1mERROR   [0m root:driver_manager.py:98 ❌ WebDriverException: Unable to connect to Appium server at http://127.0.0.1:4723/wd/hub
[31m[1mERROR   [0m root:driver_manager.py:99 🔍 Details: Message: An unknown server-side error occurred while processing the command. Original error: Could not find a connected Android device in 20000ms
Stacktrace:
UnknownError: An unknown server-side error occurred while processing the command. Original error: Could not find a connected Android device in 20000ms
    at getResponseForW3CError (/usr/local/lib/node_modules/appium/node_modules/@appium/base-driver/lib/protocol/errors.js:1143:9)
    at asyncHandler (/usr/local/lib/node_modules/appium/node_modules/@appium/base-driver/lib/protocol/protocol.js:487:57)
[31m[1mERROR   [0m mobile_framework_logger:conftest.py:49 ❌ Failed to start driver: Message: An unknown server-side error occurred while processing the command. Original error: Could not find a connected Android device in 20000ms
Stacktrace:
UnknownError: An unknown server-side error occurred while processing the command. Original error: Could not find a connected Android device in 20000ms
    at getResponseForW3CError (/usr/local/lib/node_modules/appium/node_modules/@appium/base-driver/lib/protocol/errors.js:1143:9)
    at asyncHandler (/usr/local/lib/node_modules/appium/node_modules/@appium/base-driver/lib/protocol/protocol.js:487:57)
Traceback (most recent call last):
  File "/Users/susannakarapetyan/gap_mobile/mobile_automation_framework/conftest.py", line 44, in driver
    driver = get_driver(platform)
  File "/Users/susannakarapetyan/gap_mobile/mobile_automation_framework/utils/driver_manager.py", line 89, in get_driver
    driver = webdriver.Remote(
  File "/Users/susannakarapetyan/Library/Python/3.8/lib/python/site-packages/appium/webdriver/webdriver.py", line 227, in __init__
    super().__init__(
  File "/Users/susannakarapetyan/Library/Python/3.8/lib/python/site-packages/selenium/webdriver/remote/webdriver.py", line 241, in __init__
    self.start_session(capabilities)
  File "/Users/susannakarapetyan/Library/Python/3.8/lib/python/site-packages/appium/webdriver/webdriver.py", line 319, in start_session
    response = self.execute(RemoteCommand.NEW_SESSION, w3c_caps)
  File "/Users/susannakarapetyan/Library/Python/3.8/lib/python/site-packages/selenium/webdriver/remote/webdriver.py", line 384, in execute
    self.error_handler.check_response(response)
  File "/Users/susannakarapetyan/Library/Python/3.8/lib/python/site-packages/selenium/webdriver/remote/errorhandler.py", line 232, in check_response
    raise exception_class(message, screen, stacktrace)
selenium.common.exceptions.WebDriverException: Message: An unknown server-side error occurred while processing the command. Original error: Could not find a connected Android device in 20000ms
Stacktrace:
UnknownError: An unknown server-side error occurred while processing the command. Original error: Could not find a connected Android device in 20000ms
    at getResponseForW3CError (/usr/local/lib/node_modules/appium/node_modules/@appium/base-driver/lib/protocol/errors.js:1143:9)
    at asyncHandler (/usr/local/lib/node_modules/appium/node_modules/@appium/base-driver/lib/protocol/protocol.js:487:57)
[33mWARNING [0m mobile_framework_logger:conftest.py:56 ⚠️ No driver instance found.
[32mINFO    [0m mobile_framework_logger:conftest.py:33 🛑 Stopping Appium server...
[32mINFO    [0m root:appium_server.py:50 🛑 Stopping Appium server...
[32mINFO    [0m root:appium_server.py:52 ✅ Appium server stopped.