{"uuid": "40024262-37f0-4e2c-a6f6-6dc4b8cea997", "children": ["e6780870-70bd-4c37-af66-0f61e3a94f95"], "befores": [{"name": "driver", "status": "broken", "statusDetails": {"message": "selenium.common.exceptions.WebDriverException: Message: An unknown server-side error occurred while processing the command. Original error: Could not find a connected Android device in 20000ms\nStacktrace:\nUnknownError: An unknown server-side error occurred while processing the command. Original error: Could not find a connected Android device in 20000ms\n    at getResponseForW3CError (/usr/local/lib/node_modules/appium/node_modules/@appium/base-driver/lib/protocol/errors.js:1143:9)\n    at asyncHandler (/usr/local/lib/node_modules/appium/node_modules/@appium/base-driver/lib/protocol/protocol.js:487:57)\n", "trace": "  File \"/Users/susannakarapetyan/Library/Python/3.8/lib/python/site-packages/pluggy/_callers.py\", line 167, in _multicall\n    teardown.throw(outcome._exception)\n  File \"/Users/susannakarapetyan/Library/Python/3.8/lib/python/site-packages/_pytest/setuponly.py\", line 36, in pytest_fixture_setup\n    return (yield)\n  File \"/Users/susannakarapetyan/Library/Python/3.8/lib/python/site-packages/pluggy/_callers.py\", line 103, in _multicall\n    res = hook_impl.function(*args)\n  File \"/Users/susannakarapetyan/Library/Python/3.8/lib/python/site-packages/_pytest/fixtures.py\", line 1140, in pytest_fixture_setup\n    result = call_fixture_func(fixturefunc, request, kwargs)\n  File \"/Users/susannakarapetyan/Library/Python/3.8/lib/python/site-packages/_pytest/fixtures.py\", line 891, in call_fixture_func\n    fixture_result = next(generator)\n  File \"/Users/susannakarapetyan/gap_mobile/mobile_automation_framework/conftest.py\", line 44, in driver\n    driver = get_driver(platform)\n  File \"/Users/susannakarapetyan/gap_mobile/mobile_automation_framework/utils/driver_manager.py\", line 89, in get_driver\n    driver = webdriver.Remote(\n  File \"/Users/susannakarapetyan/Library/Python/3.8/lib/python/site-packages/appium/webdriver/webdriver.py\", line 227, in __init__\n    super().__init__(\n  File \"/Users/susannakarapetyan/Library/Python/3.8/lib/python/site-packages/selenium/webdriver/remote/webdriver.py\", line 241, in __init__\n    self.start_session(capabilities)\n  File \"/Users/susannakarapetyan/Library/Python/3.8/lib/python/site-packages/appium/webdriver/webdriver.py\", line 319, in start_session\n    response = self.execute(RemoteCommand.NEW_SESSION, w3c_caps)\n  File \"/Users/susannakarapetyan/Library/Python/3.8/lib/python/site-packages/selenium/webdriver/remote/webdriver.py\", line 384, in execute\n    self.error_handler.check_response(response)\n  File \"/Users/susannakarapetyan/Library/Python/3.8/lib/python/site-packages/selenium/webdriver/remote/errorhandler.py\", line 232, in check_response\n    raise exception_class(message, screen, stacktrace)\n"}, "start": 1746514277089, "stop": 1746514298291}], "start": 1746514277089, "stop": 1746514298606}