[32mINFO    [0m mobile_framework_logger:conftest.py:30 🚀 Starting local Appium server for this session...
[32mINFO    [0m root:appium_server.py:33 🚀 Starting Appium server...
[33mWARNING [0m urllib3.connectionpool:connectionpool.py:824 Retrying (Retry(total=2, connect=None, read=None, redirect=None, status=None)) after connection broken by 'NewConnectionError('<urllib3.connection.HTTPConnection object at 0x7fd08e929bb0>: Failed to establish a new connection: [Errno 61] Connection refused')': /wd/hub/status
[33mWARNING [0m urllib3.connectionpool:connectionpool.py:824 Retrying (Retry(total=1, connect=None, read=None, redirect=None, status=None)) after connection broken by 'NewConnectionError('<urllib3.connection.HTTPConnection object at 0x7fd08e929d30>: Failed to establish a new connection: [Errno 61] Connection refused')': /wd/hub/status
[33mWARNING [0m urllib3.connectionpool:connectionpool.py:824 Retrying (Retry(total=0, connect=None, read=None, redirect=None, status=None)) after connection broken by 'NewConnectionError('<urllib3.connection.HTTPConnection object at 0x7fd08e929eb0>: Failed to establish a new connection: [Errno 61] Connection refused')': /wd/hub/status
[33mWARNING [0m urllib3.connectionpool:connectionpool.py:824 Retrying (Retry(total=2, connect=None, read=None, redirect=None, status=None)) after connection broken by 'NewConnectionError('<urllib3.connection.HTTPConnection object at 0x7fd08e94f1c0>: Failed to establish a new connection: [Errno 61] Connection refused')': /wd/hub/status
[33mWARNING [0m urllib3.connectionpool:connectionpool.py:824 Retrying (Retry(total=1, connect=None, read=None, redirect=None, status=None)) after connection broken by 'NewConnectionError('<urllib3.connection.HTTPConnection object at 0x7fd08e94f2e0>: Failed to establish a new connection: [Errno 61] Connection refused')': /wd/hub/status
[33mWARNING [0m urllib3.connectionpool:connectionpool.py:824 Retrying (Retry(total=0, connect=None, read=None, redirect=None, status=None)) after connection broken by 'NewConnectionError('<urllib3.connection.HTTPConnection object at 0x7fd08e94f490>: Failed to establish a new connection: [Errno 61] Connection refused')': /wd/hub/status
[33mWARNING [0m urllib3.connectionpool:connectionpool.py:824 Retrying (Retry(total=2, connect=None, read=None, redirect=None, status=None)) after connection broken by 'NewConnectionError('<urllib3.connection.HTTPConnection object at 0x7fd08e94f7c0>: Failed to establish a new connection: [Errno 61] Connection refused')': /wd/hub/status
[33mWARNING [0m urllib3.connectionpool:connectionpool.py:824 Retrying (Retry(total=1, connect=None, read=None, redirect=None, status=None)) after connection broken by 'NewConnectionError('<urllib3.connection.HTTPConnection object at 0x7fd08e94f940>: Failed to establish a new connection: [Errno 61] Connection refused')': /wd/hub/status
[33mWARNING [0m urllib3.connectionpool:connectionpool.py:824 Retrying (Retry(total=0, connect=None, read=None, redirect=None, status=None)) after connection broken by 'NewConnectionError('<urllib3.connection.HTTPConnection object at 0x7fd08e917e80>: Failed to establish a new connection: [Errno 61] Connection refused')': /wd/hub/status
[33mWARNING [0m urllib3.connectionpool:connectionpool.py:824 Retrying (Retry(total=2, connect=None, read=None, redirect=None, status=None)) after connection broken by 'NewConnectionError('<urllib3.connection.HTTPConnection object at 0x7fd08e917e50>: Failed to establish a new connection: [Errno 61] Connection refused')': /wd/hub/status
[33mWARNING [0m urllib3.connectionpool:connectionpool.py:824 Retrying (Retry(total=1, connect=None, read=None, redirect=None, status=None)) after connection broken by 'NewConnectionError('<urllib3.connection.HTTPConnection object at 0x7fd08e9290a0>: Failed to establish a new connection: [Errno 61] Connection refused')': /wd/hub/status
[33mWARNING [0m urllib3.connectionpool:connectionpool.py:824 Retrying (Retry(total=0, connect=None, read=None, redirect=None, status=None)) after connection broken by 'NewConnectionError('<urllib3.connection.HTTPConnection object at 0x7fd08e929520>: Failed to establish a new connection: [Errno 61] Connection refused')': /wd/hub/status
[33mWARNING [0m urllib3.connectionpool:connectionpool.py:824 Retrying (Retry(total=2, connect=None, read=None, redirect=None, status=None)) after connection broken by 'NewConnectionError('<urllib3.connection.HTTPConnection object at 0x7fd08e94f610>: Failed to establish a new connection: [Errno 61] Connection refused')': /wd/hub/status
[33mWARNING [0m urllib3.connectionpool:connectionpool.py:824 Retrying (Retry(total=1, connect=None, read=None, redirect=None, status=None)) after connection broken by 'NewConnectionError('<urllib3.connection.HTTPConnection object at 0x7fd08e94f0a0>: Failed to establish a new connection: [Errno 61] Connection refused')': /wd/hub/status
[33mWARNING [0m urllib3.connectionpool:connectionpool.py:824 Retrying (Retry(total=0, connect=None, read=None, redirect=None, status=None)) after connection broken by 'NewConnectionError('<urllib3.connection.HTTPConnection object at 0x7fd08e94fb80>: Failed to establish a new connection: [Errno 61] Connection refused')': /wd/hub/status
[33mWARNING [0m urllib3.connectionpool:connectionpool.py:824 Retrying (Retry(total=2, connect=None, read=None, redirect=None, status=None)) after connection broken by 'NewConnectionError('<urllib3.connection.HTTPConnection object at 0x7fd08e94feb0>: Failed to establish a new connection: [Errno 61] Connection refused')': /wd/hub/status
[33mWARNING [0m urllib3.connectionpool:connectionpool.py:824 Retrying (Retry(total=1, connect=None, read=None, redirect=None, status=None)) after connection broken by 'NewConnectionError('<urllib3.connection.HTTPConnection object at 0x7fd08e974070>: Failed to establish a new connection: [Errno 61] Connection refused')': /wd/hub/status
[33mWARNING [0m urllib3.connectionpool:connectionpool.py:824 Retrying (Retry(total=0, connect=None, read=None, redirect=None, status=None)) after connection broken by 'NewConnectionError('<urllib3.connection.HTTPConnection object at 0x7fd08e9741f0>: Failed to establish a new connection: [Errno 61] Connection refused')': /wd/hub/status
[33mWARNING [0m urllib3.connectionpool:connectionpool.py:824 Retrying (Retry(total=2, connect=None, read=None, redirect=None, status=None)) after connection broken by 'NewConnectionError('<urllib3.connection.HTTPConnection object at 0x7fd08e974520>: Failed to establish a new connection: [Errno 61] Connection refused')': /wd/hub/status
[33mWARNING [0m urllib3.connectionpool:connectionpool.py:824 Retrying (Retry(total=1, connect=None, read=None, redirect=None, status=None)) after connection broken by 'NewConnectionError('<urllib3.connection.HTTPConnection object at 0x7fd08e9746a0>: Failed to establish a new connection: [Errno 61] Connection refused')': /wd/hub/status
[33mWARNING [0m urllib3.connectionpool:connectionpool.py:824 Retrying (Retry(total=0, connect=None, read=None, redirect=None, status=None)) after connection broken by 'NewConnectionError('<urllib3.connection.HTTPConnection object at 0x7fd08e94fdc0>: Failed to establish a new connection: [Errno 61] Connection refused')': /wd/hub/status
[33mWARNING [0m urllib3.connectionpool:connectionpool.py:824 Retrying (Retry(total=2, connect=None, read=None, redirect=None, status=None)) after connection broken by 'NewConnectionError('<urllib3.connection.HTTPConnection object at 0x7fd08e974400>: Failed to establish a new connection: [Errno 61] Connection refused')': /wd/hub/status
[33mWARNING [0m urllib3.connectionpool:connectionpool.py:824 Retrying (Retry(total=1, connect=None, read=None, redirect=None, status=None)) after connection broken by 'NewConnectionError('<urllib3.connection.HTTPConnection object at 0x7fd08e974910>: Failed to establish a new connection: [Errno 61] Connection refused')': /wd/hub/status
[33mWARNING [0m urllib3.connectionpool:connectionpool.py:824 Retrying (Retry(total=0, connect=None, read=None, redirect=None, status=None)) after connection broken by 'NewConnectionError('<urllib3.connection.HTTPConnection object at 0x7fd08e974a90>: Failed to establish a new connection: [Errno 61] Connection refused')': /wd/hub/status
[33mWARNING [0m urllib3.connectionpool:connectionpool.py:824 Retrying (Retry(total=2, connect=None, read=None, redirect=None, status=None)) after connection broken by 'NewConnectionError('<urllib3.connection.HTTPConnection object at 0x7fd08e974dc0>: Failed to establish a new connection: [Errno 61] Connection refused')': /wd/hub/status
[33mWARNING [0m urllib3.connectionpool:connectionpool.py:824 Retrying (Retry(total=1, connect=None, read=None, redirect=None, status=None)) after connection broken by 'NewConnectionError('<urllib3.connection.HTTPConnection object at 0x7fd08e974f40>: Failed to establish a new connection: [Errno 61] Connection refused')': /wd/hub/status
[33mWARNING [0m urllib3.connectionpool:connectionpool.py:824 Retrying (Retry(total=0, connect=None, read=None, redirect=None, status=None)) after connection broken by 'NewConnectionError('<urllib3.connection.HTTPConnection object at 0x7fd08e989100>: Failed to establish a new connection: [Errno 61] Connection refused')': /wd/hub/status
[33mWARNING [0m urllib3.connectionpool:connectionpool.py:824 Retrying (Retry(total=2, connect=None, read=None, redirect=None, status=None)) after connection broken by 'NewConnectionError('<urllib3.connection.HTTPConnection object at 0x7fd08e989430>: Failed to establish a new connection: [Errno 61] Connection refused')': /wd/hub/status
[33mWARNING [0m urllib3.connectionpool:connectionpool.py:824 Retrying (Retry(total=1, connect=None, read=None, redirect=None, status=None)) after connection broken by 'NewConnectionError('<urllib3.connection.HTTPConnection object at 0x7fd08e9895b0>: Failed to establish a new connection: [Errno 61] Connection refused')': /wd/hub/status
[33mWARNING [0m urllib3.connectionpool:connectionpool.py:824 Retrying (Retry(total=0, connect=None, read=None, redirect=None, status=None)) after connection broken by 'NewConnectionError('<urllib3.connection.HTTPConnection object at 0x7fd08e989730>: Failed to establish a new connection: [Errno 61] Connection refused')': /wd/hub/status
[33mWARNING [0m urllib3.connectionpool:connectionpool.py:824 Retrying (Retry(total=2, connect=None, read=None, redirect=None, status=None)) after connection broken by 'NewConnectionError('<urllib3.connection.HTTPConnection object at 0x7fd08e989a60>: Failed to establish a new connection: [Errno 61] Connection refused')': /wd/hub/status
[33mWARNING [0m urllib3.connectionpool:connectionpool.py:824 Retrying (Retry(total=1, connect=None, read=None, redirect=None, status=None)) after connection broken by 'NewConnectionError('<urllib3.connection.HTTPConnection object at 0x7fd08e989be0>: Failed to establish a new connection: [Errno 61] Connection refused')': /wd/hub/status
[33mWARNING [0m urllib3.connectionpool:connectionpool.py:824 Retrying (Retry(total=0, connect=None, read=None, redirect=None, status=None)) after connection broken by 'NewConnectionError('<urllib3.connection.HTTPConnection object at 0x7fd08e917c70>: Failed to establish a new connection: [Errno 61] Connection refused')': /wd/hub/status
[33mWARNING [0m urllib3.connectionpool:connectionpool.py:824 Retrying (Retry(total=2, connect=None, read=None, redirect=None, status=None)) after connection broken by 'NewConnectionError('<urllib3.connection.HTTPConnection object at 0x7fd08e989cd0>: Failed to establish a new connection: [Errno 61] Connection refused')': /wd/hub/status
[33mWARNING [0m urllib3.connectionpool:connectionpool.py:824 Retrying (Retry(total=1, connect=None, read=None, redirect=None, status=None)) after connection broken by 'NewConnectionError('<urllib3.connection.HTTPConnection object at 0x7fd08e989e50>: Failed to establish a new connection: [Errno 61] Connection refused')': /wd/hub/status
[33mWARNING [0m urllib3.connectionpool:connectionpool.py:824 Retrying (Retry(total=0, connect=None, read=None, redirect=None, status=None)) after connection broken by 'NewConnectionError('<urllib3.connection.HTTPConnection object at 0x7fd08e9a9070>: Failed to establish a new connection: [Errno 61] Connection refused')': /wd/hub/status
[32mINFO    [0m root:appium_server.py:21 ✅ Appium is running at http://127.0.0.1:4723/wd/hub/status
[32mINFO    [0m root:appium_server.py:40 ✅ Appium server started successfully after 1 seconds.
[32mINFO    [0m mobile_framework_logger:conftest.py:23 🔍 Selected platform: ios
[32mINFO    [0m mobile_framework_logger:conftest.py:41 🚗 Initializing driver for platform: ios
[32mINFO    [0m root:driver_manager.py:17 🔍 Checking CONFIG for platform: ios
[32mINFO    [0m root:driver_manager.py:34 🚀 Starting Appium driver for ios (None) with capabilities: {'platformName': 'iOS', 'appium:app': '/Users/susannakarapetyan/gap_mobile/mobile_automation_framework/apps/Genius-QA.app', 'appium:deviceName': 'iPhone 14 Pro', 'appium:platformVersion': '16.4', 'appium:automationName': 'XCUITest', 'appium:useNewWDA': True, 'appium:autoAcceptAlerts': True, 'appium:autoDismissAlerts': True, 'appium:wdaLocalPort': 8100, 'appium:wdaStartupRetries': 2, 'appium:wdaLaunchTimeout': 60000, 'server_url': 'http://127.0.0.1:4723/wd/hub'}
[32mINFO    [0m root:driver_manager.py:47 ✅ IOS driver for None started.
[32mINFO    [0m mobile_framework_logger:create_genius_team_successfully_tests.py:22 🔹 Setting up Login Test
[32mINFO    [0m mobile_framework_logger:create_genius_team_successfully_tests.py:33 🔍 Running on platform: iOS
[32mINFO    [0m mobile_framework_logger:login_page.py:12 🔍 Initializing LoginPage with platform: iOS
[32mINFO    [0m mobile_framework_logger:conftest.py:53 🛑 Quitting driver after test...
[32mINFO    [0m mobile_framework_logger:conftest.py:33 🛑 Stopping Appium server...
[32mINFO    [0m root:appium_server.py:50 🛑 Stopping Appium server...
[32mINFO    [0m root:appium_server.py:52 ✅ Appium server stopped.