[32mINFO    [0m mobile_framework_logger:conftest.py:30 🚀 Starting local Appium server for this session...
[32mINFO    [0m root:appium_server.py:33 🚀 Starting Appium server...
[33mWARNING [0m urllib3.connectionpool:connectionpool.py:824 Retrying (Retry(total=2, connect=None, read=None, redirect=None, status=None)) after connection broken by 'NewConnectionError('<urllib3.connection.HTTPConnection object at 0x7f988e9364f0>: Failed to establish a new connection: [Errno 61] Connection refused')': /wd/hub/status
[33mWARNING [0m urllib3.connectionpool:connectionpool.py:824 Retrying (Retry(total=1, connect=None, read=None, redirect=None, status=None)) after connection broken by 'NewConnectionError('<urllib3.connection.HTTPConnection object at 0x7f988e936670>: Failed to establish a new connection: [Errno 61] Connection refused')': /wd/hub/status
[33mWARNING [0m urllib3.connectionpool:connectionpool.py:824 Retrying (Retry(total=0, connect=None, read=None, redirect=None, status=None)) after connection broken by 'NewConnectionError('<urllib3.connection.HTTPConnection object at 0x7f988e9367f0>: Failed to establish a new connection: [Errno 61] Connection refused')': /wd/hub/status
[33mWARNING [0m urllib3.connectionpool:connectionpool.py:824 Retrying (Retry(total=2, connect=None, read=None, redirect=None, status=None)) after connection broken by 'NewConnectionError('<urllib3.connection.HTTPConnection object at 0x7f988e9364c0>: Failed to establish a new connection: [Errno 61] Connection refused')': /wd/hub/status
[33mWARNING [0m urllib3.connectionpool:connectionpool.py:824 Retrying (Retry(total=1, connect=None, read=None, redirect=None, status=None)) after connection broken by 'NewConnectionError('<urllib3.connection.HTTPConnection object at 0x7f988e936c40>: Failed to establish a new connection: [Errno 61] Connection refused')': /wd/hub/status
[33mWARNING [0m urllib3.connectionpool:connectionpool.py:824 Retrying (Retry(total=0, connect=None, read=None, redirect=None, status=None)) after connection broken by 'NewConnectionError('<urllib3.connection.HTTPConnection object at 0x7f988e913790>: Failed to establish a new connection: [Errno 61] Connection refused')': /wd/hub/status
[33mWARNING [0m urllib3.connectionpool:connectionpool.py:824 Retrying (Retry(total=2, connect=None, read=None, redirect=None, status=None)) after connection broken by 'NewConnectionError('<urllib3.connection.HTTPConnection object at 0x7f988e9139d0>: Failed to establish a new connection: [Errno 61] Connection refused')': /wd/hub/status
[33mWARNING [0m urllib3.connectionpool:connectionpool.py:824 Retrying (Retry(total=1, connect=None, read=None, redirect=None, status=None)) after connection broken by 'NewConnectionError('<urllib3.connection.HTTPConnection object at 0x7f988e913ca0>: Failed to establish a new connection: [Errno 61] Connection refused')': /wd/hub/status
[33mWARNING [0m urllib3.connectionpool:connectionpool.py:824 Retrying (Retry(total=0, connect=None, read=None, redirect=None, status=None)) after connection broken by 'NewConnectionError('<urllib3.connection.HTTPConnection object at 0x7f988e913eb0>: Failed to establish a new connection: [Errno 61] Connection refused')': /wd/hub/status
[33mWARNING [0m urllib3.connectionpool:connectionpool.py:824 Retrying (Retry(total=2, connect=None, read=None, redirect=None, status=None)) after connection broken by 'NewConnectionError('<urllib3.connection.HTTPConnection object at 0x7f988e936a00>: Failed to establish a new connection: [Errno 61] Connection refused')': /wd/hub/status
[33mWARNING [0m urllib3.connectionpool:connectionpool.py:824 Retrying (Retry(total=1, connect=None, read=None, redirect=None, status=None)) after connection broken by 'NewConnectionError('<urllib3.connection.HTTPConnection object at 0x7f988e936df0>: Failed to establish a new connection: [Errno 61] Connection refused')': /wd/hub/status
[33mWARNING [0m urllib3.connectionpool:connectionpool.py:824 Retrying (Retry(total=0, connect=None, read=None, redirect=None, status=None)) after connection broken by 'NewConnectionError('<urllib3.connection.HTTPConnection object at 0x7f988e936f70>: Failed to establish a new connection: [Errno 61] Connection refused')': /wd/hub/status
[33mWARNING [0m urllib3.connectionpool:connectionpool.py:824 Retrying (Retry(total=2, connect=None, read=None, redirect=None, status=None)) after connection broken by 'NewConnectionError('<urllib3.connection.HTTPConnection object at 0x7f988e95c2e0>: Failed to establish a new connection: [Errno 61] Connection refused')': /wd/hub/status
[33mWARNING [0m urllib3.connectionpool:connectionpool.py:824 Retrying (Retry(total=1, connect=None, read=None, redirect=None, status=None)) after connection broken by 'NewConnectionError('<urllib3.connection.HTTPConnection object at 0x7f988e95c460>: Failed to establish a new connection: [Errno 61] Connection refused')': /wd/hub/status
[33mWARNING [0m urllib3.connectionpool:connectionpool.py:824 Retrying (Retry(total=0, connect=None, read=None, redirect=None, status=None)) after connection broken by 'NewConnectionError('<urllib3.connection.HTTPConnection object at 0x7f988e95c5e0>: Failed to establish a new connection: [Errno 61] Connection refused')': /wd/hub/status
[33mWARNING [0m urllib3.connectionpool:connectionpool.py:824 Retrying (Retry(total=2, connect=None, read=None, redirect=None, status=None)) after connection broken by 'NewConnectionError('<urllib3.connection.HTTPConnection object at 0x7f988e95c910>: Failed to establish a new connection: [Errno 61] Connection refused')': /wd/hub/status
[33mWARNING [0m urllib3.connectionpool:connectionpool.py:824 Retrying (Retry(total=1, connect=None, read=None, redirect=None, status=None)) after connection broken by 'NewConnectionError('<urllib3.connection.HTTPConnection object at 0x7f988e95ca90>: Failed to establish a new connection: [Errno 61] Connection refused')': /wd/hub/status
[33mWARNING [0m urllib3.connectionpool:connectionpool.py:824 Retrying (Retry(total=0, connect=None, read=None, redirect=None, status=None)) after connection broken by 'NewConnectionError('<urllib3.connection.HTTPConnection object at 0x7f988e913640>: Failed to establish a new connection: [Errno 61] Connection refused')': /wd/hub/status
[33mWARNING [0m urllib3.connectionpool:connectionpool.py:824 Retrying (Retry(total=2, connect=None, read=None, redirect=None, status=None)) after connection broken by 'NewConnectionError('<urllib3.connection.HTTPConnection object at 0x7f988e95cb80>: Failed to establish a new connection: [Errno 61] Connection refused')': /wd/hub/status
[33mWARNING [0m urllib3.connectionpool:connectionpool.py:824 Retrying (Retry(total=1, connect=None, read=None, redirect=None, status=None)) after connection broken by 'NewConnectionError('<urllib3.connection.HTTPConnection object at 0x7f988e95cd00>: Failed to establish a new connection: [Errno 61] Connection refused')': /wd/hub/status
[33mWARNING [0m urllib3.connectionpool:connectionpool.py:824 Retrying (Retry(total=0, connect=None, read=None, redirect=None, status=None)) after connection broken by 'NewConnectionError('<urllib3.connection.HTTPConnection object at 0x7f988e95ce80>: Failed to establish a new connection: [Errno 61] Connection refused')': /wd/hub/status
[33mWARNING [0m urllib3.connectionpool:connectionpool.py:824 Retrying (Retry(total=2, connect=None, read=None, redirect=None, status=None)) after connection broken by 'NewConnectionError('<urllib3.connection.HTTPConnection object at 0x7f988e9771f0>: Failed to establish a new connection: [Errno 61] Connection refused')': /wd/hub/status
[33mWARNING [0m urllib3.connectionpool:connectionpool.py:824 Retrying (Retry(total=1, connect=None, read=None, redirect=None, status=None)) after connection broken by 'NewConnectionError('<urllib3.connection.HTTPConnection object at 0x7f988e977370>: Failed to establish a new connection: [Errno 61] Connection refused')': /wd/hub/status
[33mWARNING [0m urllib3.connectionpool:connectionpool.py:824 Retrying (Retry(total=0, connect=None, read=None, redirect=None, status=None)) after connection broken by 'NewConnectionError('<urllib3.connection.HTTPConnection object at 0x7f988e9774f0>: Failed to establish a new connection: [Errno 61] Connection refused')': /wd/hub/status
[33mWARNING [0m urllib3.connectionpool:connectionpool.py:824 Retrying (Retry(total=2, connect=None, read=None, redirect=None, status=None)) after connection broken by 'NewConnectionError('<urllib3.connection.HTTPConnection object at 0x7f988e977820>: Failed to establish a new connection: [Errno 61] Connection refused')': /wd/hub/status
[33mWARNING [0m urllib3.connectionpool:connectionpool.py:824 Retrying (Retry(total=1, connect=None, read=None, redirect=None, status=None)) after connection broken by 'NewConnectionError('<urllib3.connection.HTTPConnection object at 0x7f988e9779a0>: Failed to establish a new connection: [Errno 61] Connection refused')': /wd/hub/status
[33mWARNING [0m urllib3.connectionpool:connectionpool.py:824 Retrying (Retry(total=0, connect=None, read=None, redirect=None, status=None)) after connection broken by 'NewConnectionError('<urllib3.connection.HTTPConnection object at 0x7f988e977b20>: Failed to establish a new connection: [Errno 61] Connection refused')': /wd/hub/status
[33mWARNING [0m urllib3.connectionpool:connectionpool.py:824 Retrying (Retry(total=2, connect=None, read=None, redirect=None, status=None)) after connection broken by 'NewConnectionError('<urllib3.connection.HTTPConnection object at 0x7f988e977e50>: Failed to establish a new connection: [Errno 61] Connection refused')': /wd/hub/status
[33mWARNING [0m urllib3.connectionpool:connectionpool.py:824 Retrying (Retry(total=1, connect=None, read=None, redirect=None, status=None)) after connection broken by 'NewConnectionError('<urllib3.connection.HTTPConnection object at 0x7f988e977f10>: Failed to establish a new connection: [Errno 61] Connection refused')': /wd/hub/status
[33mWARNING [0m urllib3.connectionpool:connectionpool.py:824 Retrying (Retry(total=0, connect=None, read=None, redirect=None, status=None)) after connection broken by 'NewConnectionError('<urllib3.connection.HTTPConnection object at 0x7f988e9776a0>: Failed to establish a new connection: [Errno 61] Connection refused')': /wd/hub/status
[33mWARNING [0m urllib3.connectionpool:connectionpool.py:824 Retrying (Retry(total=2, connect=None, read=None, redirect=None, status=None)) after connection broken by 'NewConnectionError('<urllib3.connection.HTTPConnection object at 0x7f988e990100>: Failed to establish a new connection: [Errno 61] Connection refused')': /wd/hub/status
[33mWARNING [0m urllib3.connectionpool:connectionpool.py:824 Retrying (Retry(total=1, connect=None, read=None, redirect=None, status=None)) after connection broken by 'NewConnectionError('<urllib3.connection.HTTPConnection object at 0x7f988e990280>: Failed to establish a new connection: [Errno 61] Connection refused')': /wd/hub/status
[33mWARNING [0m urllib3.connectionpool:connectionpool.py:824 Retrying (Retry(total=0, connect=None, read=None, redirect=None, status=None)) after connection broken by 'NewConnectionError('<urllib3.connection.HTTPConnection object at 0x7f988e990400>: Failed to establish a new connection: [Errno 61] Connection refused')': /wd/hub/status
[32mINFO    [0m root:appium_server.py:21 ✅ Appium is running at http://127.0.0.1:4723/wd/hub/status
[32mINFO    [0m root:appium_server.py:40 ✅ Appium server started successfully after 1 seconds.
[32mINFO    [0m mobile_framework_logger:conftest.py:23 🔍 Selected platform: ios
[32mINFO    [0m mobile_framework_logger:conftest.py:41 🚗 Initializing driver for platform: ios
[32mINFO    [0m root:driver_manager.py:17 🔍 Checking CONFIG for platform: ios
[32mINFO    [0m root:driver_manager.py:34 🚀 Starting Appium driver for ios (None) with capabilities: {'platformName': 'iOS', 'appium:app': '/Users/susannakarapetyan/gap_mobile/mobile_automation_framework/apps/Genius-QA.app', 'appium:deviceName': 'iPhone 14 Pro', 'appium:platformVersion': '16.4', 'appium:automationName': 'XCUITest', 'appium:useNewWDA': True, 'appium:autoAcceptAlerts': True, 'appium:autoDismissAlerts': True, 'appium:wdaLocalPort': 8100, 'appium:wdaStartupRetries': 2, 'appium:wdaLaunchTimeout': 60000, 'server_url': 'http://127.0.0.1:4723/wd/hub'}
[32mINFO    [0m root:driver_manager.py:47 ✅ IOS driver for None started.
[32mINFO    [0m mobile_framework_logger:create_genius_team_successfully_tests.py:20 🔹 Setting up Login Test
[32mINFO    [0m mobile_framework_logger:create_genius_team_successfully_tests.py:31 🔍 Running on platform: iOS
[32mINFO    [0m mobile_framework_logger:login_page.py:12 🔍 Initializing LoginPage with platform: iOS
[32mINFO    [0m mobile_framework_logger:login_page.py:23 🔄 Verifying that the login screen is displayed on iOS...
[32mINFO    [0m mobile_framework_logger:login_page.py:31 ✅ Login screen is displayed on iOS.
[32mINFO    [0m mobile_framework_logger:create_genius_team_successfully_tests.py:40 🔹 Running valid login test on: iOS
[32mINFO    [0m mobile_framework_logger:create_genius_team_successfully_tests.py:44 🔐 Logging in with: NewLGOBCO1@mailinator.com / qwe123QWE!@#
[32mINFO    [0m mobile_framework_logger:login_page.py:39 🔹 Performing valid login on iOS with email: NewLGOBCO1@mailinator.com
[32mINFO    [0m mobile_framework_logger:base_page.py:93 ✅ Sent keys to ('-ios predicate string', 'value == "Email"'): NewLGOBCO1@mailinator.com
[32mINFO    [0m mobile_framework_logger:base_page.py:93 ✅ Sent keys to ('-ios predicate string', 'value == "Password"'): qwe123QWE!@#
[32mINFO    [0m mobile_framework_logger:base_page.py:37 ⏳ Waiting for element to be visible: ('-ios predicate string', 'value == "Sign In"')
[32mINFO    [0m mobile_framework_logger:base_page.py:40 ✅ Clicked on ('-ios predicate string', 'value == "Sign In"')
[32mINFO    [0m mobile_framework_logger:login_page.py:54 ✅ Login button clicked successfully.
[32mINFO    [0m mobile_framework_logger:dashboard_page.py:34 ✅ Dashboard tab is visible on the Dashboard.
[32mINFO    [0m mobile_framework_logger:create_genius_team_successfully_tests.py:47 ✅ Login test completed successfully!
[32mINFO    [0m mobile_framework_logger:dashboard_page.py:54 🔹 Clicking GM tab...
[32mINFO    [0m mobile_framework_logger:base_page.py:37 ⏳ Waiting for element to be visible: ('-ios predicate string', 'label == "icon genius meter"')
[32mINFO    [0m mobile_framework_logger:base_page.py:40 ✅ Clicked on ('-ios predicate string', 'label == "icon genius meter"')
[32mINFO    [0m mobile_framework_logger:dashboard_page.py:56 ✅ GM tab clicked successfully!
[32mINFO    [0m mobile_framework_logger:GM_page.py:24 🔹 Scrolling to the bottom of the GM page...
[32mINFO    [0m mobile_framework_logger:base_page.py:239 🔍 Element 'create_team_btn' not initially visible. Starting scroll...
[32mINFO    [0m mobile_framework_logger:base_page.py:246 📱 iOS: Scrolling up
[32mINFO    [0m mobile_framework_logger:base_page.py:278 🔄 Still not visible after 1 scroll(s)...
[32mINFO    [0m mobile_framework_logger:base_page.py:246 📱 iOS: Scrolling up
[32mINFO    [0m mobile_framework_logger:base_page.py:278 🔄 Still not visible after 2 scroll(s)...
[32mINFO    [0m mobile_framework_logger:base_page.py:246 📱 iOS: Scrolling up
[32mINFO    [0m mobile_framework_logger:base_page.py:278 🔄 Still not visible after 3 scroll(s)...
[32mINFO    [0m mobile_framework_logger:base_page.py:246 📱 iOS: Scrolling up
[32mINFO    [0m mobile_framework_logger:base_page.py:275 ✅ Found element 'create_team_btn' after 4 scroll(s).
[32mINFO    [0m mobile_framework_logger:GM_page.py:29 ✅ Reached the bottom of the GM page.
[32mINFO    [0m mobile_framework_logger:GM_page.py:63 🔹 Clicking Create a team...
[32mINFO    [0m mobile_framework_logger:base_page.py:37 ⏳ Waiting for element to be visible: ('-ios predicate string', 'label == "Create a Team" AND name == "Create a Team" AND type == "XCUIElementTypeButton"')
[32mINFO    [0m mobile_framework_logger:base_page.py:40 ✅ Clicked on ('-ios predicate string', 'label == "Create a Team" AND name == "Create a Team" AND type == "XCUIElementTypeButton"')
[32mINFO    [0m mobile_framework_logger:GM_page.py:65 ✅ Create a team is clicked successfully!
[32mINFO    [0m mobile_framework_logger:GM_create_team.py:39 ✅ create_team_title is visible on the Create a team screen.
[32mINFO    [0m mobile_framework_logger:GM_create_team.py:103 📝 Filling out GM team creation fields with:
[32mINFO    [0m mobile_framework_logger:GM_create_team.py:104    • Team Name: 5GRP=+h)h}ng
[32mINFO    [0m mobile_framework_logger:GM_create_team.py:105    • Project Name: K}s^2msq=vG)
[32mINFO    [0m mobile_framework_logger:GM_create_team.py:106    • Outcome: Os8aYkco]G}T
[32mINFO    [0m mobile_framework_logger:GM_create_team.py:117 🔹 Focusing and typing into Team Name field...
[32mINFO    [0m mobile_framework_logger:base_page.py:37 ⏳ Waiting for element to be visible: ('accessibility id', 'Enter team name…')
[32mINFO    [0m mobile_framework_logger:base_page.py:40 ✅ Clicked on ('accessibility id', 'Enter team name…')
[32mINFO    [0m mobile_framework_logger:base_page.py:93 ✅ Sent keys to ('accessibility id', 'Team Name'): 5GRP=+h)h}ng
[32mINFO    [0m mobile_framework_logger:GM_create_team.py:122 🔹 Focusing and typing into Project Name field...
[32mINFO    [0m mobile_framework_logger:base_page.py:37 ⏳ Waiting for element to be visible: ('accessibility id', 'Enter project name…')
[32mINFO    [0m mobile_framework_logger:base_page.py:40 ✅ Clicked on ('accessibility id', 'Enter project name…')
[32mINFO    [0m mobile_framework_logger:base_page.py:93 ✅ Sent keys to ('accessibility id', 'Project Name'): K}s^2msq=vG)
[32mINFO    [0m mobile_framework_logger:GM_create_team.py:127 🔹 Focusing and typing into Outcome field...
[32mINFO    [0m mobile_framework_logger:base_page.py:37 ⏳ Waiting for element to be visible: ('accessibility id', 'Enter outcome…')
[32mINFO    [0m mobile_framework_logger:base_page.py:40 ✅ Clicked on ('accessibility id', 'Enter outcome…')
[32mINFO    [0m mobile_framework_logger:base_page.py:93 ✅ Sent keys to ('accessibility id', 'Outcome'): Os8aYkco]G}T
[32mINFO    [0m mobile_framework_logger:GM_create_team.py:130 ✅ GM team form filled successfully.
[32mINFO    [0m mobile_framework_logger:GM_create_team.py:168 ⏳ Waiting for 'Submit' button to be visible...
[32mINFO    [0m mobile_framework_logger:GM_create_team.py:170 ✅ 'Submit' button is visible. Clicking now...
[32mINFO    [0m mobile_framework_logger:GM_create_team.py:172 ✅ 'Submit' button clicked successfully.
[32mINFO    [0m mobile_framework_logger:conftest.py:53 🛑 Quitting driver after test...
[32mINFO    [0m mobile_framework_logger:conftest.py:33 🛑 Stopping Appium server...
[32mINFO    [0m root:appium_server.py:50 🛑 Stopping Appium server...
[32mINFO    [0m root:appium_server.py:52 ✅ Appium server stopped.