[32mINFO    [0m mobile_framework_logger:conftest.py:30 🚀 Starting local Appium server for this session...
[32mINFO    [0m root:appium_server.py:33 🚀 Starting Appium server...
[33mWARNING [0m urllib3.connectionpool:connectionpool.py:824 Retrying (Retry(total=2, connect=None, read=None, redirect=None, status=None)) after connection broken by 'NewConnectionError('<urllib3.connection.HTTPConnection object at 0x7f8d63818b50>: Failed to establish a new connection: [Errno 61] Connection refused')': /wd/hub/status
[33mWARNING [0m urllib3.connectionpool:connectionpool.py:824 Retrying (Retry(total=1, connect=None, read=None, redirect=None, status=None)) after connection broken by 'NewConnectionError('<urllib3.connection.HTTPConnection object at 0x7f8d63818cd0>: Failed to establish a new connection: [Errno 61] Connection refused')': /wd/hub/status
[33mWARNING [0m urllib3.connectionpool:connectionpool.py:824 Retrying (Retry(total=0, connect=None, read=None, redirect=None, status=None)) after connection broken by 'NewConnectionError('<urllib3.connection.HTTPConnection object at 0x7f8d63818e50>: Failed to establish a new connection: [Errno 61] Connection refused')': /wd/hub/status
[33mWARNING [0m urllib3.connectionpool:connectionpool.py:824 Retrying (Retry(total=2, connect=None, read=None, redirect=None, status=None)) after connection broken by 'NewConnectionError('<urllib3.connection.HTTPConnection object at 0x7f8d6380ae80>: Failed to establish a new connection: [Errno 61] Connection refused')': /wd/hub/status
[33mWARNING [0m urllib3.connectionpool:connectionpool.py:824 Retrying (Retry(total=1, connect=None, read=None, redirect=None, status=None)) after connection broken by 'NewConnectionError('<urllib3.connection.HTTPConnection object at 0x7f8d6380ad30>: Failed to establish a new connection: [Errno 61] Connection refused')': /wd/hub/status
[33mWARNING [0m urllib3.connectionpool:connectionpool.py:824 Retrying (Retry(total=0, connect=None, read=None, redirect=None, status=None)) after connection broken by 'NewConnectionError('<urllib3.connection.HTTPConnection object at 0x7f8d6380ab20>: Failed to establish a new connection: [Errno 61] Connection refused')': /wd/hub/status
[33mWARNING [0m urllib3.connectionpool:connectionpool.py:824 Retrying (Retry(total=2, connect=None, read=None, redirect=None, status=None)) after connection broken by 'NewConnectionError('<urllib3.connection.HTTPConnection object at 0x7f8d63818610>: Failed to establish a new connection: [Errno 61] Connection refused')': /wd/hub/status
[33mWARNING [0m urllib3.connectionpool:connectionpool.py:824 Retrying (Retry(total=1, connect=None, read=None, redirect=None, status=None)) after connection broken by 'NewConnectionError('<urllib3.connection.HTTPConnection object at 0x7f8d638180d0>: Failed to establish a new connection: [Errno 61] Connection refused')': /wd/hub/status
[33mWARNING [0m urllib3.connectionpool:connectionpool.py:824 Retrying (Retry(total=0, connect=None, read=None, redirect=None, status=None)) after connection broken by 'NewConnectionError('<urllib3.connection.HTTPConnection object at 0x7f8d6383e130>: Failed to establish a new connection: [Errno 61] Connection refused')': /wd/hub/status
[33mWARNING [0m urllib3.connectionpool:connectionpool.py:824 Retrying (Retry(total=2, connect=None, read=None, redirect=None, status=None)) after connection broken by 'NewConnectionError('<urllib3.connection.HTTPConnection object at 0x7f8d6383e3d0>: Failed to establish a new connection: [Errno 61] Connection refused')': /wd/hub/status
[33mWARNING [0m urllib3.connectionpool:connectionpool.py:824 Retrying (Retry(total=1, connect=None, read=None, redirect=None, status=None)) after connection broken by 'NewConnectionError('<urllib3.connection.HTTPConnection object at 0x7f8d6383e550>: Failed to establish a new connection: [Errno 61] Connection refused')': /wd/hub/status
[33mWARNING [0m urllib3.connectionpool:connectionpool.py:824 Retrying (Retry(total=0, connect=None, read=None, redirect=None, status=None)) after connection broken by 'NewConnectionError('<urllib3.connection.HTTPConnection object at 0x7f8d6383e6d0>: Failed to establish a new connection: [Errno 61] Connection refused')': /wd/hub/status
[33mWARNING [0m urllib3.connectionpool:connectionpool.py:824 Retrying (Retry(total=2, connect=None, read=None, redirect=None, status=None)) after connection broken by 'NewConnectionError('<urllib3.connection.HTTPConnection object at 0x7f8d6383ea00>: Failed to establish a new connection: [Errno 61] Connection refused')': /wd/hub/status
[33mWARNING [0m urllib3.connectionpool:connectionpool.py:824 Retrying (Retry(total=1, connect=None, read=None, redirect=None, status=None)) after connection broken by 'NewConnectionError('<urllib3.connection.HTTPConnection object at 0x7f8d6383eb80>: Failed to establish a new connection: [Errno 61] Connection refused')': /wd/hub/status
[33mWARNING [0m urllib3.connectionpool:connectionpool.py:824 Retrying (Retry(total=0, connect=None, read=None, redirect=None, status=None)) after connection broken by 'NewConnectionError('<urllib3.connection.HTTPConnection object at 0x7f8d6383ed00>: Failed to establish a new connection: [Errno 61] Connection refused')': /wd/hub/status
[33mWARNING [0m urllib3.connectionpool:connectionpool.py:824 Retrying (Retry(total=2, connect=None, read=None, redirect=None, status=None)) after connection broken by 'NewConnectionError('<urllib3.connection.HTTPConnection object at 0x7f8d6383e280>: Failed to establish a new connection: [Errno 61] Connection refused')': /wd/hub/status
[33mWARNING [0m urllib3.connectionpool:connectionpool.py:824 Retrying (Retry(total=1, connect=None, read=None, redirect=None, status=None)) after connection broken by 'NewConnectionError('<urllib3.connection.HTTPConnection object at 0x7f8d6383eee0>: Failed to establish a new connection: [Errno 61] Connection refused')': /wd/hub/status
[33mWARNING [0m urllib3.connectionpool:connectionpool.py:824 Retrying (Retry(total=0, connect=None, read=None, redirect=None, status=None)) after connection broken by 'NewConnectionError('<urllib3.connection.HTTPConnection object at 0x7f8d638660a0>: Failed to establish a new connection: [Errno 61] Connection refused')': /wd/hub/status
[33mWARNING [0m urllib3.connectionpool:connectionpool.py:824 Retrying (Retry(total=2, connect=None, read=None, redirect=None, status=None)) after connection broken by 'NewConnectionError('<urllib3.connection.HTTPConnection object at 0x7f8d638663d0>: Failed to establish a new connection: [Errno 61] Connection refused')': /wd/hub/status
[33mWARNING [0m urllib3.connectionpool:connectionpool.py:824 Retrying (Retry(total=1, connect=None, read=None, redirect=None, status=None)) after connection broken by 'NewConnectionError('<urllib3.connection.HTTPConnection object at 0x7f8d63866550>: Failed to establish a new connection: [Errno 61] Connection refused')': /wd/hub/status
[33mWARNING [0m urllib3.connectionpool:connectionpool.py:824 Retrying (Retry(total=0, connect=None, read=None, redirect=None, status=None)) after connection broken by 'NewConnectionError('<urllib3.connection.HTTPConnection object at 0x7f8d638666d0>: Failed to establish a new connection: [Errno 61] Connection refused')': /wd/hub/status
[33mWARNING [0m urllib3.connectionpool:connectionpool.py:824 Retrying (Retry(total=2, connect=None, read=None, redirect=None, status=None)) after connection broken by 'NewConnectionError('<urllib3.connection.HTTPConnection object at 0x7f8d63866a00>: Failed to establish a new connection: [Errno 61] Connection refused')': /wd/hub/status
[33mWARNING [0m urllib3.connectionpool:connectionpool.py:824 Retrying (Retry(total=1, connect=None, read=None, redirect=None, status=None)) after connection broken by 'NewConnectionError('<urllib3.connection.HTTPConnection object at 0x7f8d63866b80>: Failed to establish a new connection: [Errno 61] Connection refused')': /wd/hub/status
[33mWARNING [0m urllib3.connectionpool:connectionpool.py:824 Retrying (Retry(total=0, connect=None, read=None, redirect=None, status=None)) after connection broken by 'NewConnectionError('<urllib3.connection.HTTPConnection object at 0x7f8d63866d00>: Failed to establish a new connection: [Errno 61] Connection refused')': /wd/hub/status
[33mWARNING [0m urllib3.connectionpool:connectionpool.py:824 Retrying (Retry(total=2, connect=None, read=None, redirect=None, status=None)) after connection broken by 'NewConnectionError('<urllib3.connection.HTTPConnection object at 0x7f8d6387f070>: Failed to establish a new connection: [Errno 61] Connection refused')': /wd/hub/status
[33mWARNING [0m urllib3.connectionpool:connectionpool.py:824 Retrying (Retry(total=1, connect=None, read=None, redirect=None, status=None)) after connection broken by 'NewConnectionError('<urllib3.connection.HTTPConnection object at 0x7f8d6387f1f0>: Failed to establish a new connection: [Errno 61] Connection refused')': /wd/hub/status
[33mWARNING [0m urllib3.connectionpool:connectionpool.py:824 Retrying (Retry(total=0, connect=None, read=None, redirect=None, status=None)) after connection broken by 'NewConnectionError('<urllib3.connection.HTTPConnection object at 0x7f8d63866f40>: Failed to establish a new connection: [Errno 61] Connection refused')': /wd/hub/status
[33mWARNING [0m urllib3.connectionpool:connectionpool.py:824 Retrying (Retry(total=2, connect=None, read=None, redirect=None, status=None)) after connection broken by 'NewConnectionError('<urllib3.connection.HTTPConnection object at 0x7f8d63866fd0>: Failed to establish a new connection: [Errno 61] Connection refused')': /wd/hub/status
[33mWARNING [0m urllib3.connectionpool:connectionpool.py:824 Retrying (Retry(total=1, connect=None, read=None, redirect=None, status=None)) after connection broken by 'NewConnectionError('<urllib3.connection.HTTPConnection object at 0x7f8d6387f460>: Failed to establish a new connection: [Errno 61] Connection refused')': /wd/hub/status
[33mWARNING [0m urllib3.connectionpool:connectionpool.py:824 Retrying (Retry(total=0, connect=None, read=None, redirect=None, status=None)) after connection broken by 'NewConnectionError('<urllib3.connection.HTTPConnection object at 0x7f8d6387f5e0>: Failed to establish a new connection: [Errno 61] Connection refused')': /wd/hub/status
[33mWARNING [0m urllib3.connectionpool:connectionpool.py:824 Retrying (Retry(total=2, connect=None, read=None, redirect=None, status=None)) after connection broken by 'NewConnectionError('<urllib3.connection.HTTPConnection object at 0x7f8d6387f910>: Failed to establish a new connection: [Errno 61] Connection refused')': /wd/hub/status
[33mWARNING [0m urllib3.connectionpool:connectionpool.py:824 Retrying (Retry(total=1, connect=None, read=None, redirect=None, status=None)) after connection broken by 'NewConnectionError('<urllib3.connection.HTTPConnection object at 0x7f8d6387fa90>: Failed to establish a new connection: [Errno 61] Connection refused')': /wd/hub/status
[33mWARNING [0m urllib3.connectionpool:connectionpool.py:824 Retrying (Retry(total=0, connect=None, read=None, redirect=None, status=None)) after connection broken by 'NewConnectionError('<urllib3.connection.HTTPConnection object at 0x7f8d6387fc10>: Failed to establish a new connection: [Errno 61] Connection refused')': /wd/hub/status
[32mINFO    [0m root:appium_server.py:21 ✅ Appium is running at http://127.0.0.1:4723/wd/hub/status
[32mINFO    [0m root:appium_server.py:40 ✅ Appium server started successfully after 1 seconds.
[32mINFO    [0m mobile_framework_logger:conftest.py:23 🔍 Selected platform: ios
[32mINFO    [0m mobile_framework_logger:conftest.py:41 🚗 Initializing driver for platform: ios
[32mINFO    [0m root:driver_manager.py:17 🔍 Checking CONFIG for platform: ios
[32mINFO    [0m root:driver_manager.py:34 🚀 Starting Appium driver for ios (None) with capabilities: {'platformName': 'iOS', 'appium:app': '/Users/susannakarapetyan/gap_mobile/mobile_automation_framework/apps/Genius-QA.app', 'appium:deviceName': 'iPhone 14 Pro', 'appium:platformVersion': '16.4', 'appium:automationName': 'XCUITest', 'appium:useNewWDA': True, 'appium:autoAcceptAlerts': True, 'appium:autoDismissAlerts': True, 'appium:wdaLocalPort': 8100, 'appium:wdaStartupRetries': 2, 'appium:wdaLaunchTimeout': 60000, 'server_url': 'http://127.0.0.1:4723/wd/hub'}
[32mINFO    [0m root:driver_manager.py:47 ✅ IOS driver for None started.
[32mINFO    [0m mobile_framework_logger:create_genius_team_successfully_tests.py:22 🔹 Setting up Login Test
[32mINFO    [0m mobile_framework_logger:create_genius_team_successfully_tests.py:33 🔍 Running on platform: iOS
[32mINFO    [0m mobile_framework_logger:login_page.py:12 🔍 Initializing LoginPage with platform: iOS
[32mINFO    [0m mobile_framework_logger:login_page.py:23 🔄 Verifying that the login screen is displayed on iOS...
[32mINFO    [0m mobile_framework_logger:login_page.py:31 ✅ Login screen is displayed on iOS.
[32mINFO    [0m mobile_framework_logger:create_genius_team_successfully_tests.py:48 🔹 Running valid login test on: iOS
[32mINFO    [0m mobile_framework_logger:create_genius_team_successfully_tests.py:52 🔐 Logging in with: andranik.hayrapetyan@volo.global / qwe123QWE!@#
[32mINFO    [0m mobile_framework_logger:login_page.py:39 🔹 Performing valid login on iOS with email: andranik.hayrapetyan@volo.global
[32mINFO    [0m mobile_framework_logger:base_page.py:93 ✅ Sent keys to ('-ios predicate string', 'value == "Email"'): andranik.hayrapetyan@volo.global
[32mINFO    [0m mobile_framework_logger:base_page.py:93 ✅ Sent keys to ('-ios predicate string', 'value == "Password"'): qwe123QWE!@#
[32mINFO    [0m mobile_framework_logger:base_page.py:37 ⏳ Waiting for element to be visible: ('-ios predicate string', 'value == "Sign In"')
[32mINFO    [0m mobile_framework_logger:base_page.py:40 ✅ Clicked on ('-ios predicate string', 'value == "Sign In"')
[32mINFO    [0m mobile_framework_logger:login_page.py:54 ✅ Login button clicked successfully.
[32mINFO    [0m mobile_framework_logger:conftest.py:53 🛑 Quitting driver after test...
[32mINFO    [0m mobile_framework_logger:conftest.py:33 🛑 Stopping Appium server...
[32mINFO    [0m root:appium_server.py:50 🛑 Stopping Appium server...
[32mINFO    [0m root:appium_server.py:52 ✅ Appium server stopped.